<?xml version="1.0"?>
<robot xmlns:xacro="http://www.ros.org/wiki/xacro">


    <xacro:include filename="$(find cyton_ros2_gazebo)/urdf/cyton_gazebo.xacro" />
    <xacro:include filename="$(find cyton_ros2_gazebo)/urdf/cyton_transmission.xacro" />

    <xacro:macro name="cyton_robot">

        <xacro:cyton_transmission />
        <xacro:cyton_gazebo />

        <!-- Initial footprint motor used here -->
        <xacro:macro name="base_footprint">
            <link name="base_footprint">
                <!-- ZMIENIĆ!!! -->
                <inertial>
                    <mass value="2.92"/>
                    <origin rpy="0 0 0" xyz="-0.025566 -2.88e-05 0.057332"/>
                    <inertia ixx="0.00782229414331" ixy="-1.56191622996e-05" ixz="-0.00126005738123" iyy="0.0109027971813" iyz="1.08233858202e-05" izz="0.0102355503949"/>
                  </inertial>
                <!-- ZMIENIĆ -->
                <visual>
                    <origin xyz="0 0 1" rpy="0 0 0" />
                    <geometry>
                        <sphere radius="0.001" />
                    </geometry>
                    <material name="white">
                        <color rgba="1 1 1 1" />
                    </material>
                </visual>
                <collision>
                    <origin xyz="0 0 0" rpy="0 0 0" />
                    <geometry>
                        <sphere radius="0.001" />
                    </geometry>
                </collision>
            </link>

            <joint name="base_joint" type="fixed">
                <parent link="base_footprint" />
                <child link="base_link" />
                <dynamics damping="0.5" friction="0.5"/>
                <origin xyz="0.0 0.0 0.0" rpy="0 0 0" />
            </joint>
        </xacro:macro>

        <!-- Base of robot here -->
        <link name="base_link">
            <visual>
                <origin xyz="0 0 0" rpy="0 0 0" />
                <geometry>
                    <mesh filename="file://$(find cyton_ros2_gazebo)/meshes/visual/gamma_base.dae" />
                </geometry>
            </visual>
            <collision>
                <origin xyz="0 0.0115 0.047" />
                <geometry>
                    <box size="0.01 0.01 0.01" />
                </geometry>
            </collision>
            <inertial>
                <mass value="100.0" />
                <origin rpy="0 0 0" xyz="0 0 0" />
                <inertia ixx="1.1027" iyy="1.1027" izz="1.1027"
                    ixy="0.05" ixz="0.05" iyz="0.05" />
            </inertial>
        </link>

        <!-- First motor located here -->
        <joint name="shoulder_roll_joint" type="revolute">
            <parent link="base_link" />
            <child link="shoulder_roll" />
            <origin xyz="0 0 0.05315" rpy="0 0 1.2" />
            <dynamics damping="0.5" friction="0.5"/>
            <limit lower="-2.618" upper="2.618" effort="7.0" velocity="1.0" />
            <axis xyz="0 0 1" />
        </joint>

        <link name="shoulder_roll">
            <visual>
                <origin xyz="0 0 0" rpy="1.5708 0 3.14159" />
                <geometry>
                    <mesh filename="file://$(find cyton_ros2_gazebo)/meshes/visual/Shoulder_Roll.dae" />
                </geometry>
            </visual>
            <collision>
                <origin xyz="0.0 0.069 0.0587" />
                <geometry>
                    <box size="0.09829 0.18143 0.08392" />
                </geometry>
            </collision>
            <inertial>
                <mass value="50.0" />
                <origin rpy="0 0 0" xyz="0 0 0" />
                <inertia ixx=".1027" iyy=".1027" izz=".1027"
                    ixy="0.05" ixz="0.05" iyz="0.05" />
            </inertial>
        </link>

        <!-- Second motor located here -->
        <joint name="shoulder_pitch_joint" type="revolute">
            <parent link="shoulder_roll" />
            <child link="shoulder_pitch" />
            <origin xyz="0 0 0.063" rpy="1.2 0 0" />
            <dynamics damping="0.5" friction="0.5"/>
            <limit lower="-1.8326" upper="1.8326" effort="7.0" velocity="1.0" />
            <axis xyz="1 0 0" />
        </joint>

        <link name="shoulder_pitch">
            <visual>
                <origin xyz="0.028 0 0" rpy="0 1.5708 0" />
                <geometry>
                    <mesh filename="file://$(find cyton_ros2_gazebo)/meshes/visual/Shoulder_Pitch.dae" />
                </geometry>
            </visual>
            <collision>
                <origin xyz="-0.001 0.064 0.1745" />
                <geometry>
                    <box size="0.0709 0.19363 0.083" />
                </geometry>
            </collision>
            <inertial>
                <mass value="20.0" />
                <origin rpy="0 0 0" xyz="0 0 0" />
                <inertia ixx=".0827" iyy=".0827" izz=".0827"
                    ixy="0.05" ixz="0.05" iyz="0.05" />
            </inertial>
        </link>
<!-- TUTAJ ODPIERDALA -->
        <!-- Third motor located here -->
        <joint name="elbow_roll_joint" type="revolute">
            <parent link="shoulder_pitch" />
            <child link="elbow_roll" />
            <origin xyz="0 0 0.089" rpy="0 0 1.2" />
            <dynamics damping="0.5" friction="0.5"/>
            <limit lower="-1.8326" upper="1.8326" effort="7.0" velocity="1.0" />
            <axis xyz="0 0 1" />
        </joint>

        <link name="elbow_roll">
            <visual>
                <origin xyz="0 0 0" rpy="0 0 3.92699" />
                <geometry>
                    <mesh filename="file://$(find cyton_ros2_gazebo)/meshes/visual/Elbow_Roll.dae" />
                </geometry>
            </visual>
            <collision>
                <origin xyz="-0.0225 0.039 0.3068" />
                <geometry>
                    <box size="0.0717 0.1846 0.0756" />
                </geometry>
            </collision>
            <inertial>
                <mass value="10.0" />
                <origin rpy="0 0 0" xyz="0 0 0" />
                <inertia ixx=".0627" iyy=".0627" izz=".0627"
                    ixy="0.05" ixz="0.05" iyz="0.05" />
            </inertial>
        </link>

        <!-- Fourth motor located here -->
        <joint name="elbow_pitch_joint" type="revolute">
            <parent link="elbow_roll" />
            <child link="elbow_pitch" />
            <origin xyz="0 0 0.052" rpy="1.2 0 0" />
            <dynamics damping="0.5" friction="0.5"/>
            <limit lower="-1.8326" upper="1.8326" effort="7.0" velocity="1.0" />
            <axis xyz="1 0 0" />
        </joint>

        <link name="elbow_pitch">
            <visual>
                <!-- Not sure if this is the correct orientation. -->
                <origin xyz="0.027 0 0" rpy="1.5708 0 1.5708" />
                <geometry>
                    <mesh filename="file://$(find cyton_ros2_gazebo)/meshes/visual/Elbow_Pitch.dae" />
                </geometry>
            </visual>
            <collision>
                <origin xyz="0.0346 0.0461 0.4228" />
                <geometry>
                    <box size="0.0549 0.1557 0.076" />
                </geometry>
            </collision>
            <inertial>
                <mass value="10.0" />
                <origin rpy="0 0 0" xyz="0 0 0" />
                <inertia ixx=".0327" iyy=".0327" izz=".0327"
                    ixy="0.05" ixz="0.05" iyz="0.05" />
            </inertial>
        </link>

        <!-- Fifth motor located here -->
        <joint name="elbow_yaw_joint" type="revolute">
            <parent link="elbow_pitch" />
            <child link="elbow_yaw" />
            <origin xyz="0 0 0.072" rpy="0 -1.2 0" />
            <dynamics damping="0.5" friction="0.5"/>
            <limit lower="-1.8326" upper="1.8326" effort="7.0" velocity="1.0" />
            <axis xyz="0 -1 0" />
        </joint>

        <link name="elbow_yaw">
            <visual>
                <origin xyz="0 0 0" rpy="1.5708 0 0" />
                <geometry>
                    <mesh filename="file://$(find cyton_ros2_gazebo)/meshes/visual/Elbow_Yaw.dae" />
                </geometry>
            </visual>
            <collision>
                <origin xyz="0.0172 0.0209 0.516" />
                <geometry>
                    <box size="0.0535 0.1160 0.0402" />
                </geometry>
            </collision>
            <inertial>
                <mass value="10.0" />
                <origin rpy="0 0 0" xyz="0 0 0" />
                <inertia ixx=".0227" iyy=".0227" izz=".0227"
                    ixy="0.05" ixz="0.05" iyz="0.05" />
            </inertial>
        </link>

        <!-- Sixth motor located here -->
        <joint name="wrist_pitch_joint" type="revolute">
            <parent link="elbow_yaw" />
            <child link="wrist_pitch" />
            <origin xyz="0 0 0.0718" rpy="1.2 0 0" />
            <dynamics damping="0.5" friction="0.5"/>
            <limit lower="-1.8326" upper="1.8326" effort="7.0" velocity="1.0" />
            <axis xyz="1 0 0" />
        </joint>

        <link name="wrist_pitch">
            <visual>
                <origin xyz="0.027 0 0" rpy="1.5708 0 1.5708" />
                <geometry>
                    <mesh filename="file://$(find cyton_ros2_gazebo)/meshes/visual/Wrist_Pitch.dae" />
                </geometry>
            </visual>
            <collision>
                <origin xyz="0.0257 0.0118 0.5617" />
                <geometry>
                    <box size="0.026 0.0435 0.05185" />
                </geometry>
            </collision>
            <inertial>
                <mass value="10.0" />
                <origin rpy="0 0 0" xyz="0 0 0" />
                <inertia ixx=".0127" iyy=".0127" izz=".0127"
                    ixy="0.05" ixz="0.05" iyz="0.05" />
            </inertial>
        </link>

        <!-- Seventh motor located here -->
        <joint name="wrist_roll_joint" type="revolute">
            <parent link="wrist_pitch" />
            <child link="wrist_roll" />
            <origin xyz="0 0 0.051425" rpy="0 0 1.2" />
            <dynamics damping="0.5" friction="0.5"/>
            <limit lower="-2.61799" upper="2.61799" effort="7.0" velocity="1.0" />
            <axis xyz="0 0 1" />
        </joint>

        <link name="wrist_roll">
            <visual>
                <origin xyz="0 0 0" rpy="0 3.14159 1.5708" />
                <geometry>
                    <mesh filename="file://$(find cyton_ros2_gazebo)/meshes/visual/Wrist_Roll.dae" />
                </geometry>
            </visual>
            <collision>
                <origin xyz="-0.0063 -0.0014 0.6102" />
                <geometry>
                    <box size="0.0518 0.0723 0.1004" />
                </geometry>
            </collision>
            <inertial>
                <mass value="10.0" />
                <origin rpy="0 0 0" xyz="0 0 0" />
                <inertia ixx=".0027" iyy=".0027" izz=".0027"
                    ixy="0.05" ixz="0.05" iyz="0.05" />
            </inertial>
        </link>

        <!-- Eigth motor located here -->
        <!-- <joint name="gripper_joint" type="prismatic">
            <parent link="wrist_roll" />
            <child link="gripper_finger1" />
            <origin xyz="-0.01331 0.00485 0.077225" rpy="0 0 0" />
            <limit lower="-0.008" upper="0.008" effort="7.0" velocity="1.0" />
            <axis xyz="1 0 0" />
        </joint>

        <link name="gripper_finger1">
            <visual>
                <origin xyz="0 0 0" rpy="0 0 0" />
                <geometry>
                    <mesh filename="file://$(find cyton_ros2_gazebo)/meshes/visual/Gripper_Finger1.dae"/>
                </geometry>
            </visual>
            <collision>
                <origin xyz="-0.0167 0.0172 0.7254"/>
                <geometry>
                    <box size="0.015 0.0229 0.0475"/>
                </geometry>
            </collision>
        </link> -->

        <!-- Eighth motor located here -->
        <!-- <joint name="gripper_joint2" type="prismatic">
            <parent link="wrist_roll" />
            <child link="gripper_finger2" />
            <origin xyz="0.0098 0.00485 0.077225" rpy="0 0 0" />
            <limit lower="-0.008" upper="0.008" effort="7.0" velocity="1.0" />
            <mimic joint="gripper_joint" multiplier="-1"/>
            <axis xyz="1 0 0" />
        </joint>

        <link name="gripper_finger2">
            <visual>
                <origin xyz="0 0 0" rpy="0 0 0" />
                <geometry>
                    <mesh filename="file://$(find cyton_ros2_gazebo)/meshes/visual/Gripper_Finger2.dae"/>
                </geometry>
            </visual>
            <collision>
                <origin xyz="0.0132 0.0172 0.7254"/>
                <geometry>
                    <box size="0.015 0.0229 0.0475"/>
                </geometry>
            </collision>
        </link> -->

        <!-- <xacro:if value="${virtual_ee}">
            <joint name="virtual_endeffector_joint" type="fixed">
                <parent link="wrist_roll" />
                <child link="virtual_endeffector" />
                <origin xyz="-0.002316 0.0079 0.079425" rpy="0 0 0" />
            </joint>

            <link name="virtual_endeffector">
                <visual>
                    <origin xyz="0 0 0" rpy="0 0 0" />
                    <geometry>
                        <sphere radius="0.002" />
                    </geometry>
                    <material name="grey">
                        <color rgba="0.7 0.7 0.7 0.8" />
                    </material>
                </visual>
            </link>
        </xacro:if> -->
    </xacro:macro>

</robot>